Workbook

Sheet Synthèse
A1: SYNTHÈSE BUDGÉTAIRE — Monique Festival
A3: Catégorie | B3: Recettes prévues | C3: Recettes réelles | D3: Écart recettes | E3: Dépenses prévues | F3: Dépenses réelles | G3: Écart dépenses | H3: Marge prévue | I3: Marge réelle | J3: Écart marge
A4: Crowdfunding | B4: =Crowdfunding!C16 | C4: =Crowdfunding!D16 | D4: =C4-B4 | E4: 0 | F4: 0 | G4: =F4-E4 | H4: =B4-E4 | I4: =C4-F4 | J4: =I4-H4
A5: Billetterie + Artistes | B5: =Billetterie!D10 | C5: =Billetterie!F10 | D5: =C5-B5 | E5: =Artistes!F36+Artistes!G36+Artistes!H36 | F5: =Artistes!J36+Artistes!K36 | G5: =F5-E5 | H5: =B5-E5 | I5: =C5-F5 | J5: =I5-H5
A6: F&B (Buvettes + Restauration) | B6: ='F&B'!D13 | C6: ='F&B'!E13 | D6: =C6-B6 | E6: ='F&B'!D27 | F6: ='F&B'!E27 | G6: =F6-E6 | H6: =B6-E6 | I6: =C6-F6 | J6: =I6-H6
A7: Ateliers (recettes + coûts ateliers) | B7: =Ateliers!D14 | C7: =Ateliers!E14 | D7: =C7-B7 | E7: =Ateliers!D27 | F7: =Ateliers!E27 | G7: =F7-E7 | H7: =B7-E7 | I7: =C7-F7 | J7: =I7-H7
A8: Logistique | B8: 0 | C8: 0 | D8: =C8-B8 | E8: =Logistique!C18 | F8: =Logistique!D18 | G8: =F8-E8 | H8: =B8-E8 | I8: =C8-F8 | J8: =I8-H8
A9: Frais divers | B9: ='Frais divers'!D12 | C9: ='Frais divers'!E12 | D9: =C9-B9 | E9: ='Frais divers'!D29 | F9: ='Frais divers'!E29 | G9: =F9-E9 | H9: =B9-E9 | I9: =C9-F9 | J9: =I9-H9
A11: (ajustement défraiement supprimé : 150€ moyen intégré directement) | E11: 0
A12: TOTAL | B12: =SUM(B4:B11) | C12: =SUM(C4:C11) | D12: =SUM(D4:D11) | E12: =SUM(E4:E11) | F12: =SUM(F4:F11) | G12: =SUM(G4:G11) | H12: =SUM(H4:H11) | I12: =SUM(I4:I11) | J12: =SUM(J4:J11)
A15: SCÉNARIOS PAR JAUGE
A17: Scénario | B17: Recettes | C17: Coûts | D17: Marge | E17: Jauge | F17: Nb festivaliers
A18: Jauge -20% | B18: 47464 | C18: 47767 | D18: -303 | E18: 960 | F18: 960
A19: Jauge standard | B19: 58482 | C19: 49907 | D19: 8575 | E19: 1 200 | F19: 1200
A20: Jauge +20% | B20: 69500 | C20: 52048 | D20: 17453 | E20: 1 440 | F20: 1440

Sheet Crowdfunding
A1: CROWDFUNDING — Recettes HelloAsso
A3: Date | B3: Description | C3: Prévu | D3: Réel | E3: Écart
B4: Objectif crowdfunding (palier 3) | C4: 8000 | E4: =D4-C4
E5: =D5-C5
E6: =D6-C6
E7: =D7-C7
E8: =D8-C8
E9: =D9-C9
E10: =D10-C10
E11: =D11-C11
E12: =D12-C12
E13: =D13-C13
E14: =D14-C14
A16: TOTAL CROWDFUNDING | C16: =SUM(C4:C14) | D16: =SUM(D4:D14) | E16: =SUM(E4:E14)

Sheet Billetterie
A1: BILLETTERIE — Recettes
A3: Type | B3: Tarif | C3: Nb prévu | D3: Recettes prévues | E3: Nb réel | F3: Recettes réelles | G3: Écart
A4: Early bird pass 3 jours | B4: 20 | C4: 120 | D4: =B4*C4 | F4: =B4*E4 | G4: =F4-D4
A5: Pass 3 jours | B5: 25 | C5: 480 | D5: =B5*C5 | F5: =B5*E5 | G5: =F5-D5
A6: Vendredi | B6: 10 | C6: 150 | D6: =B6*C6 | F6: =B6*E6 | G6: =F6-D6
A7: Samedi | B7: 15 | C7: 300 | D7: =B7*C7 | F7: =B7*E7 | G7: =F7-D7
A8: Dimanche | B8: 15 | C8: 150 | D8: =B8*C8 | F8: =B8*E8 | G8: =F8-D8
A10: TOTAL BILLETTERIE | C10: =SUM(C4:C8) | D10: =SUM(D4:D8) | E10: =SUM(E4:E8) | F10: =SUM(F4:F8) | G10: =SUM(G4:G8)

Sheet F&B
A1: F&B — Buvettes + Restauration (Scénario B — validé 03/05/2026)
A3: RECETTES par jour
A5: Date | B5: Description | C5: Type | D5: Prévu | E5: Réel | F5: Écart
B6: Buvette Vendredi : bière 1200 + vin 540 + soft 793 + café 81 | C6: Recette | D6: 2614 | F6: =E6-D6
B7: Buvette Samedi : bière 4600 + vin 1950 + soft 3439 + café 477 (jour fort) | C7: Recette | D7: 10466 | F7: =E7-D7
B8: Buvette Dimanche : bière 600 + vin 340 + soft 1188 + café 162 | C8: Recette | D8: 2290 | F8: =E8-D8
B9: Restauration repas Vendredi : 225 assiettes (70% Grande 12€ / 30% Petite 9€, FC ou végé) | C9: Recette | D9: 2498 | F9: =E9-D9
B10: Restauration repas Samedi : 650 assiettes (Petite 9€ / Grande 12€, FC ou végé) | C10: Recette | D10: 7215 | F10: =E10-D10
B11: Restauration repas Dimanche : 225 assiettes (Petite 9€ / Grande 12€, FC ou végé) | C11: Recette | D11: 2498 | F11: =E11-D11
B12: Snacks Vendredi : pop-corn 60 (40p × 1,50€) + frites 120 + glaces 109 + tomates 150 (100p × 1,50€) | C12: Recette | D12: 439 | F12: =E12-D12
B13: Snacks Samedi : pop-corn 428 (285p × 1,50€) + frites 705 + glaces 850 + tomates 435 (290p × 1,50€) | C13: Recette | D13: 2418 | F13: =E13-D13
B14: Snacks Dimanche : pop-corn 120 (80p × 1,50€) + frites 240 + glaces 218 + tomates 165 (110p × 1,50€) | C14: Recette | D14: 743 | F14: =E14-D14
B15: Consignes écocup non remboursées (1 000 écocups × 20 % non-retour × 1 €) | C15: Recette | D15: 200 | F15: =E15-D15
A16: TOTAL RECETTES F&B | D16: =SUM(D6:D15) | E16: =SUM(E6:E15) | F16: =E16-D16
A18: COÛTS FIXES (incompressibles — indépendants de la fréquentation)
A20: Date | B20: Description | C20: Type | D20: Prévu | E20: Réel | F20: Écart
B21: Percolateurs 4 × 10 L (ABC LOCATION) | C21: Dépense | D21: 345 | F21: =E21-D21
B22: Friteuses × 2 (ABC LOCATION) | C22: Dépense | D22: 172 | F22: =E22-D22
B23: Machine pop-corn (location) | C23: Dépense | D23: 252 | F23: =E23-D23
B24: Eau gratuite : fontaines + carafes (charge éthique) | C24: Dépense | D24: 400 | F24: =E24-D24
B25: HACCP : tablier + charlotte + gants jetables + sonde T° + désinfectant | C25: Dépense | D25: 80 | F25: =E25-D25
B26: Lavage écocups + sacs poubelles tri + récup huile usagée | C26: Dépense | D26: 120 | F26: =E26-D26
B27: Trousse premiers secours buvette | C27: Dépense | D27: 30 | F27: =E27-D27
B28: Affichage prix (ardoises + marqueurs) + caisse + ustensiles préparation | C28: Dépense | D28: 310 | F28: =E28-D28
A29: TOTAL FIXES | D29: =SUM(D21:D28) | E29: =SUM(E21:E28) | F29: =E29-D29
A31: INVESTISSEMENT semi-fixe (amortissable sur éditions futures)
A33: Date | B33: Description | C33: Type | D33: Prévu | E33: Réel | F33: Écart
B34: Écocups réutilisables Atomic — 1 000 pièces 25 cL (réutilisables éditions futures) | C34: Invest | D34: 600 | F34: =E34-D34
A35: TOTAL INVEST | D35: =SUM(D34:D34) | E35: =SUM(E34:E34) | F35: =E35-D35
A37: COÛTS VARIABLES (proportionnels à la fréquentation, ajustables)
A39: Date | B39: Description | C39: Type | D39: Prévu | E39: Réel | F39: Écart
B40: Bière Le Pintadier — 10 fûts initial (commande ferme) | C40: Dépense | D40: 800 | F40: =E40-D40
B41: Bière Le Pintadier — 5 fûts réassort éventuel (à activer vendredi soir si forte demande — +3200 € recettes) | C41: Dépense | D41: 0 | F41: =E41-D41
B42: Vin Cubi Jura 5 L (Hyper Boisson, prix négocié 50 €/cubi) × 29 cubis | C42: Dépense | D42: 1450 | F42: =E42-D42
B43: Soft : sirop 300 + jus 350 + Mortuacienne 58 + eau pét. 35 + eau plate 32 | C43: Dépense | D43: 775 | F43: =E43-D43
B44: Café : poudre BFC + sucre + lait + mélangeurs + gobelets bio | C44: Dépense | D44: 110 | F44: =E44-D44
B45: Sucre bar additionnel + glace pilée bar | C45: Dépense | D45: 60 | F45: =E45-D45
B46: Pop-corn (1 flousy=1,50€) : maïs 10kg (15) + huile/sel (8) + gobelets bio 72cL (40) — 405 portions | C46: Dépense | D46: 63 | F46: =E46-D46
B47: Frites snack : pdt 50kg BFC (60) + huile (32) + sel (2) + barquettes (18) + sauces (36) — 360 portions | C47: Dépense | D47: 148 | F47: =E47-D47
B48: Glaces ERHARD (1 boule=1,50€/2 boules=3€) : 39 bacs 2,5L (94) + cornets gaufrette 560 (67) + back-up (3) — 560 portions, mix 60/40 | C48: Dépense | D48: 164 | F48: =E48-D48
...

Sheet Ateliers
A1: ATELIERS — Recettes & Dépenses
A3: Recettes (cotisations participants)
A5: Date | B5: Description | C5: Type | D5: Prévu | E5: Réel | F5: Écart
B6: Masterclass chant lyrique (4 élèves × 60 €) | C6: Recette | D6: 240 | F6: =E6-D6
B7: Atelier écriture (15 pers × 50 € + 150 € lycée) | C7: Recette | D7: 900 | F7: =E7-D7
B8: Atelier musique & théâtre (30 pers × 50 €) | C8: Recette | D8: 1500 | F8: =E8-D8
B9: Atelier DJ (15 pers × 50 €) | C9: Recette | D9: 750 | F9: =E9-D9
F10: =E10-D10
F11: =E11-D11
F12: =E12-D12
A14: TOTAL RECETTES ATELIERS | D14: =SUM(D6:D12) | E14: =SUM(E6:E12) | F14: =SUM(F6:F12)
A16: Dépenses (intervenants ateliers)
A18: Date | B18: Description | C18: Type | D18: Prévu | E18: Réel | F18: Écart
B19: Rép. Fabulo (4 art. x 2 jours x 100€) | C19: Dépense | D19: 800 | F19: =E19-D19
B20: Rép. Masterclass chant — Romane (incl. Fabulo) | C20: Dépense | D20: 0 | F20: =E20-D20
B21: Rép. Atelier écriture — Sylvain (2 jours x 100€) | C21: Dépense | D21: 200 | F21: =E21-D21
B22: Rép. Atelier DJ — Jeff (2 jours x 100€) | C22: Dépense | D22: 200 | F22: =E22-D22
F23: =E23-D23
F24: =E24-D24
F25: =E25-D25
A27: TOTAL DÉPENSES ATELIERS | D27: =SUM(D19:D25) | E27: =SUM(E19:E25) | F27: =SUM(F19:F25)

Sheet Artistes
A1: ARTISTES — Dépenses (cachet 250€, rép. 100€, défr. 200€ max)
A3: Georges Cabaret (Sète, 34) - France hors BFC | B3: Musique | D3: 1 | E3: 0 | F3: 250 | G3: 0 | H3: 150 | I3: 400 | L3: 0 | N3: -400
A4: Loretta (locale) | B4: Musique | D4: 1 | E4: 0 | F4: 250 | G4: 0 | H4: 0 | I4: 250 | L4: 0 | N4: -250
A5: Fanélie Nava | B5: Musique | D5: 1 | E5: 0 | F5: 250 | G5: 0 | H5: 150 | I5: 400 | L5: 0 | N5: -400
A6: Manu - Wambo (local) | B6: Musique | D6: 1 | E6: 0 | F6: 250 | G6: 0 | H6: 0 | I6: 250 | L6: 0 | N6: -250
A7: Antoine Vermot - Jeff The Fool (local, parents BFC) | B7: Musique | C7: Atelier DJ | D7: 0 | E7: 2 | F7: 0 | G7: 200 | H7: 0 | I7: 200 | L7: 0 | N7: -200
A8: Wet Enough?! (5 art.) | B8: Musique — Collectif | D8: 5 | E8: 0 | F8: 1250 | G8: 0 | H8: 750 | I8: 2000 | L8: 0 | N8: -2000
A9: Osmosis (3 art.) | B9: Musique — Collectif | D9: 3 | E9: 0 | F9: 750 | G9: 0 | H9: 450 | I9: 1200 | L9: 0 | N9: -1200
A10: Vladimir Torres Trio (3 art.) - France hors BFC | B10: Musique — Collectif | D10: 3 | E10: 0 | F10: 750 | G10: 0 | H10: 450 | I10: 1200 | L10: 0 | N10: -1200
A11: Kaïnza (3 art.) | B11: Musique — Collectif | D11: 3 | E11: 0 | F11: 750 | G11: 0 | H11: 450 | I11: 1200 | L11: 0 | N11: -1200
A12: Léopold (famille) | B12: Musique | C12: Atelier DJ | D12: 0 | E12: 2 | F12: 0 | G12: 0 | H12: 0 | I12: 0 | L12: 0 | N12: 0
A13: Luther (famille) | B13: Musique | D13: 0 | E13: 0 | F13: 0 | G13: 0 | H13: 0 | I13: 0 | L13: 0 | N13: 0
A14: Marius (Fabulo) | B14: Fabulo — Collectif | C14: Musique & théâtre | D14: 2 | E14: 2 | F14: 500 | G14: 200 | H14: 150 | I14: 850 | L14: 0 | N14: -850
A15: Maya (Fabulo) | B15: Fabulo — Collectif | C15: Musique & théâtre | D15: 2 | E15: 2 | F15: 500 | G15: 200 | H15: 150 | I15: 850 | L15: 0 | N15: -850
A16: Raphaëlle (Fabulo) | B16: Fabulo — Collectif | C16: Musique & théâtre | D16: 2 | E16: 2 | F16: 500 | G16: 200 | H16: 150 | I16: 850 | L16: 0 | N16: -850
A17: Romane Cabaret (vient avec Lorraine) | B17: Fabulo — Collectif | C17: Masterclass chant | D17: 4 | E17: 2 | F17: 1000 | G17: 200 | H17: 0 | I17: 1200 | L17: 0 | N17: -1200
A18: Lorraine (famille) | B18: Fabulo | C18: Musique & théâtre | D18: 0 | E18: 0 | F18: 0 | G18: 0 | H18: 0 | I18: 0 | L18: 0 | N18: 0
A19: Marc Trembovelski | B19: Classique | D19: 2 | E19: 0 | F19: 500 | G19: 0 | H19: 200 | I19: 700 | L19: 0 | N19: -700
A20: Sophie Ehling | B20: Classique | D20: 2 | E20: 0 | F20: 500 | G20: 0 | H20: 200 | I20: 700 | L20: 0 | N20: -700
A21: Jakub Wycislik | B21: Classique | D21: 2 | E21: 0 | F21: 500 | G21: 0 | H21: 200 | I21: 700 | L21: 0 | N21: -700
A22: Beatriz Correia | B22: Classique | D22: 2 | E22: 0 | F22: 500 | G22: 0 | H22: 200 | I22: 700 | L22: 0 | N22: -700
A23: Volodia Van Keulen | B23: Classique | D23: 2 | E23: 0 | F23: 500 | G23: 0 | H23: 150 | I23: 650 | L23: 0 | N23: -650
A24: Augustin Lemonnier (pianiste) | B24: Classique | D24: 1 | E24: 0 | F24: 250 | G24: 0 | H24: 150 | I24: 400 | L24: 0 | N24: -400
A25: Nils Van Keulen (Masterclass) | B25: Classique | C25: Masterclass chant | D25: 0 | E25: 1 | F25: 0 | G25: 100 | H25: 0 | I25: 100 | L25: 0 | N25: -100
A26: Sylvain Septours (vient avec Lewis) | B26: Théâtre | C26: Atelier écriture | D26: 0 | E26: 2 | F26: 0 | G26: 200 | H26: 0 | I26: 200 | L26: 0 | N26: -200
A27: Marius Ponnelle (Treize Clique) | B27: Théâtre — Collectif | D27: 1 | E27: 0 | F27: 250 | G27: 0 | H27: 150 | I27: 400 | L27: 0 | N27: -400
A28: Comédien 2 (Treize Clique) | B28: Théâtre — Collectif | D28: 1 | E28: 0 | F28: 250 | G28: 0 | H28: 150 | I28: 400 | L28: 0 | N28: -400
A29: Comédien 3 (Treize Clique) | B29: Théâtre — Collectif | D29: 1 | E29: 0 | F29: 250 | G29: 0 | H29: 150 | I29: 400 | L29: 0 | N29: -400
A30: Lewis (famille) | B30: Théâtre | C30: Éloquence | D30: 0 | E30: 0 | F30: 0 | G30: 0 | H30: 0 | I30: 0 | L30: 0 | N30: 0
A31: Cie Nenni ma foi - Patatra (4 art.) | B31: Théâtre — Coll AP | D31: 4 | E31: 0 | F31: 1000 | G31: 0 | H31: 0 | I31: 1000 | L31: 0 | N31: -1000
A32: Cie Vous faites un feu? (2 art.) | B32: Théâtre — Coll AP | D32: 2 | E32: 0 | F32: 500 | G32: 0 | H32: 0 | I32: 500 | L32: 0 | N32: -500
A33: Cie Derrière le mur - Trafic (2 art.) | B33: Théâtre — Coll AP | D33: 2 | E33: 0 | F33: 500 | G33: 0 | H33: 0 | I33: 500 | L33: 0 | N33: -500
A34: Cie L'Entre - V.I.E.N.S dimanche (3 art.) | B34: Théâtre — Coll AP | D34: 3 | E34: 0 | F34: 750 | G34: 0 | H34: 0 | I34: 750 | L34: 0 | N34: -750
A35: À travers la fenêtre des heures (2 art.) - Belgique | B35: Classique — Coll | D35: 2 | E35: 0 | F35: 500 | G35: 0 | H35: 400 | I35: 900 | L35: 0 | N35: -900
A36: TOTAL ARTISTES | D36: =SUM(D3:D35) | E36: =SUM(E3:E35) | F36: =SUM(F3:F35) | G36: =SUM(G3:G35) | H36: =SUM(H3:H35) | I36: =SUM(I3:I35) | J36: =SUM(J3:J35) | K36: =SUM(K3:K35) | L36: =SUM(L3:L35) | N36: =SUM(N3:N35)

Sheet Logistique
A1: LOGISTIQUE — Dépenses
A3: Date | B3: Description | C3: Prévu | D3: Réel | E3: Écart
B4: Location salle / terrain | C4: 3000 | E4: =D4-C4
B5: Sonorisation | C5: 3000 | E5: =D5-C5
B6: Éclairage / lumière | C6: 2000 | E6: =D6-C6
B7: Scène / podium | C7: 2000 | E7: =D7-C7
B8: Toilettes / sanitaires | C8: 1500 | E8: =D8-C8
B9: Électricité / groupe électrogène | C9: 1500 | E9: =D9-C9
B10: Barrières / sécurité | C10: 1000 | E10: =D10-C10
B11: Mobilier (tables, chaises, tentes) | C11: 1000 | E11: =D11-C11
E12: =D12-C12
E13: =D13-C13
E14: =D14-C14
E15: =D15-C15
E16: =D16-C16
A18: TOTAL LOGISTIQUE | C18: =SUM(C4:C16) | D18: =SUM(D4:D16) | E18: =SUM(E4:E16)

Sheet Frais divers
A1: FRAIS DIVERS — Recettes & Dépenses
A3: Recettes (subventions, dons, sponsors)
A5: Date | B5: Description | C5: Type | D5: Prévu | E5: Réel | F5: Écart
F6: =E6-D6
F7: =E7-D7
F8: =E8-D8
F9: =E9-D9
F10: =E10-D10
A12: TOTAL RECETTES DIVERS | D12: =SUM(D6:D10) | E12: =SUM(E6:E10) | F12: =SUM(F6:F10)
A14: Dépenses (SACEM, communication, assurance, admin, imprévus)
A16: Date | B16: Description | C16: Type | D16: Prévu | E16: Réel | F16: Écart
B17: SACEM Billetterie (8,8%) | C17: Dépense | D17: 1993 | F17: =E17-D17
B18: SACEM Restauration/Buvettes (4,4%) | C18: Dépense | D18: 1427 | F18: =E18-D18
B19: Assurance événement | C19: Dépense | D19: 1000 | F19: =E19-D19
B20: Communication (affiches, flyers, vidéo) | C20: Dépense | D20: 1000 | F20: =E20-D20
B21: Frais administratifs | C21: Dépense | D21: 500 | F21: =E21-D21
B22: Imprévus | C22: Dépense | D22: 500 | F22: =E22-D22
F23: =E23-D23
F24: =E24-D24
F25: =E25-D25
F26: =E26-D26
F27: =E27-D27
A29: TOTAL DÉPENSES DIVERS | D29: =SUM(D17:D27) | E29: =SUM(E17:E27) | F29: =SUM(F17:F27)

Sheet Trésorerie
A1: TRÉSORERIE — Flux par date
A3: Solde initial | D3: 0 | F3: 0
A4: 23/04/2026 | B4: Crowdfunding HelloAsso | C4: Cumul dons collectés au 23/04 (14 dons) | D4: 845 | F4: =D2+D4-E4
A5: 20/04/2026 | B5: Don manuel Charles | C5: Don manuel par virement Qonto | D5: 1000 | F5: =F4+D5-E5
A6: Avr-Mai 2026 | B6: Frais divers | C6: Petites dépenses opérationnelles (cumul estimation) | E6: 255 | F6: =F5+D6-E6
A7: 01/05/2026 | B7: Crowdfunding HelloAsso | C7: Cumul dons supplémentaires (23/04 → 01/05) | D7: 360 | F7: =F6+D7-E7
A8: TOTAUX | D8: =SUM(D4:D7) | E8: =SUM(E4:E7) | F8: =F7
A10: SOLDE Qonto au 01/05/2026 (estimation) | F10: =F7
